<?xml version="1.0" ?>
<robot xmlns:xacro="http://ros.org/wiki/xacro">

  <xacro:macro name="ur5_joints_links">

    <!-- links main serial chain -->

    <link name="world" />
    <link name="box">
      <visual>
        <origin xyz="0 0 0.5" rpy="0 0 0"/> 
        <geometry>
          <box size="0.5 0.5 1.0"/> 
        </geometry>
        <material name="white"/>
      </visual>

      <collision>
        <origin xyz="0 0 0.5" rpy="0 0 0"/>
        <geometry>
          <box size="0.5 0.5 1.00"/>
        </geometry>
      </collision>

     <inertial>
      <origin xyz="0 0 0.5"/>
      <mass value="500.0"/>
      <inertia
        ixx="104.167" ixy="0" ixz="0"
        iyy="104.167" iyz="0"
        izz="20.833"/>
      </inertial>
    </link>

    <link name="base_link">
      <visual>
        <origin rpy="0 0 3.141592653589793" xyz="0 0 0" />
        <geometry>
          <mesh filename="package://ur5_description/meshes/base.dae" />
        </geometry>
        <material name="LightGrey">
          <color rgba="0.7 0.7 0.7 1.0" />
        </material>
      </visual>
      <collision>
        <origin rpy="0 0 3.141592653589793" xyz="0 0 0" />
        <geometry>
          <mesh filename="package://ur5_description/meshes/base.dae" />
        </geometry>
      </collision>
      <inertial>
        <mass value="4.0" />
        <origin rpy="0 0 0" xyz="0 0 0" />
        <inertia ixx="0.00443333156" ixy="0.0" ixz="0.0" iyy="0.00443333156" iyz="0.0" izz="0.0072" />
      </inertial>
    </link>

    <link name="shoulder_link">
      <visual>
        <origin rpy="0 0 3.141592653589793" xyz="0 0 0" />
        <geometry>
          <mesh filename="package://ur5_description/meshes/shoulder.dae" />
        </geometry>
        <material name="LightGrey">
          <color rgba="0.7 0.7 0.7 1.0" />
        </material>
      </visual>
      <collision>
        <origin rpy="0 0 3.141592653589793" xyz="0 0 0" />
        <geometry>
          <mesh filename="package://ur5_description/meshes/shoulder.dae" />
        </geometry>
      </collision>
      <inertial>
        <mass value="3.7" />
        <origin rpy="0 0 0" xyz="0 0 0" />
        <inertia ixx="0.010267495893" ixy="0.0" ixz="0.0" iyy="0.010267495893" iyz="0.0"
          izz="0.00666" />
      </inertial>
    </link>

    <link name="upper_arm_link">
      <visual>
        <origin rpy="1.5707963267948966 0 -1.5707963267948966" xyz="0 0 0.138" />
        <geometry>
          <mesh filename="package://ur5_description/meshes/upperarm.dae" />
        </geometry>
        <material name="LightGrey">
          <color rgba="0.7 0.7 0.7 1.0" />
        </material>
      </visual>
      <collision>
        <origin rpy="1.5707963267948966 0 -1.5707963267948966" xyz="0 0 0.138" />
        <geometry>
          <mesh filename="package://ur5_description/meshes/upperarm.dae" />
        </geometry>
      </collision>
      <inertial>
        <mass value="8.393" />
        <origin rpy="0 1.5707963267948966 0" xyz="-0.2125 0.0 0.138" />
        <inertia ixx="0.1338857818623325" ixy="0.0" ixz="0.0" iyy="0.1338857818623325" iyz="0.0"
          izz="0.0151074" />
      </inertial>
    </link>

    <link name="forearm_link">
      <visual>
        <origin rpy="1.5707963267948966 0 -1.5707963267948966" xyz="0 0 0.007" />
        <geometry>
          <mesh filename="package://ur5_description/meshes/forearm.dae" />
        </geometry>
        <material name="LightGrey">
          <color rgba="0.7 0.7 0.7 1.0" />
        </material>
      </visual>
      <collision>
        <origin rpy="1.5707963267948966 0 -1.5707963267948966" xyz="0 0 0.007" />
        <geometry>
          <mesh filename="package://ur5_description/meshes/forearm.dae" />
        </geometry>
      </collision>
      <inertial>
        <mass value="2.275" />
        <origin rpy="0 1.5707963267948966 0" xyz="-0.1961 0.0 0.007" />
        <inertia ixx="0.031209355099586295" ixy="0.0" ixz="0.0" iyy="0.031209355099586295" iyz="0.0"
          izz="0.004095" />
      </inertial>
    </link>

    <link name="wrist_1_link">
      <visual>
        <origin rpy="1.5707963267948966 0 0" xyz="0 0 -0.127" />
        <geometry>
          <mesh filename="package://ur5_description/meshes/wrist1.dae" />
        </geometry>
        <material name="LightGrey">
          <color rgba="0.7 0.7 0.7 1.0" />
        </material>
      </visual>
      <collision>
        <origin rpy="1.5707963267948966 0 0" xyz="0 0 -0.127" />
        <geometry>
          <mesh filename="package://ur5_description/meshes/wrist1.dae" />
        </geometry>
      </collision>
      <inertial>
        <mass value="1.219" />
        <origin rpy="0 0 0" xyz="0 0 0" />
        <inertia ixx="0.0025598989760400002" ixy="0.0" ixz="0.0" iyy="0.0025598989760400002"
          iyz="0.0" izz="0.0021942" />
      </inertial>
    </link>

    <link name="wrist_2_link">
      <visual>
        <origin rpy="0 0 0" xyz="0 0 -0.0997" />
        <geometry>
          <mesh filename="package://ur5_description/meshes/wrist2.dae" />
        </geometry>
        <material name="LightGrey">
          <color rgba="0.7 0.7 0.7 1.0" />
        </material>
      </visual>
      <collision>
        <origin rpy="0 0 0" xyz="0 0 -0.0997" />
        <geometry>
          <mesh filename="package://ur5_description/meshes/wrist2.dae" />
        </geometry>
      </collision>
      <inertial>
        <mass value="1.219" />
        <origin rpy="0 0 0" xyz="0 0 0" />
        <inertia ixx="0.0025598989760400002" ixy="0.0" ixz="0.0" iyy="0.0025598989760400002"
          iyz="0.0" izz="0.0021942" />
      </inertial>
    </link>
    
    <link name="wrist_3_link">
      <visual>
        <origin rpy="1.5707963267948966 0 0" xyz="0 0 -0.0989" />
        <geometry>
          <mesh filename="package://ur5_description/meshes/wrist3.dae" />
        </geometry>
        <material name="LightGrey">
          <color rgba="0.7 0.7 0.7 1.0" />
        </material>
      </visual>
      <collision>
        <origin rpy="1.5707963267948966 0 0" xyz="0 0 -0.0989" />
        <geometry>
          <mesh filename="package://ur5_description/meshes/wrist3.dae" />
        </geometry>
      </collision>
      <inertial>
        <mass value="0.1879" />
        <origin rpy="0 0 0" xyz="0.0 0.0 -0.0229" />
        <inertia ixx="9.890410052167731e-05" ixy="0.0" ixz="0.0" iyy="9.890410052167731e-05"
          iyz="0.0" izz="0.0001321171875" />
      </inertial>
    </link>
    <!-- right hand link and joint-->
     <link
    name="r_palm">
    <inertial>
      <origin
        xyz="-0.00099373 0.040537 -0.0022835"
        rpy="0 0 0" />
      <mass
        value="0.427" />
      <inertia
        ixx="3.4364E-05"
        ixy="-1.2404E-06"
        ixz="5.654E-07"
        iyy="3.9467E-05"
        iyz="3.8955E-06"
        izz="6.3984E-05" />
    </inertial>
    <visual>
      <origin
        xyz="0 0 0"
        rpy="0 0 0" />
      <geometry>
        <mesh
          filename="package://ur5_description/meshes/r_palm.STL" />
      </geometry>
      <material
        name="">
        <color
          rgba="0.75294 0.75294 0.75294 1" />
      </material>
    </visual>
    <collision>
      <origin
        xyz="0 0 0"
        rpy="0 0 0" />
      <geometry>
        <mesh
          filename="package://ur5_description/meshes/r_palm.STL" />
      </geometry>
    </collision>
  </link>
  <link
    name="r_thumb_prox">
    <inertial>
      <origin
        xyz="0.0062041 -7.9383E-08 0.0015306"
        rpy="0 0 0" />
      <mass
        value="0.005" />
      <inertia
        ixx="4.0639E-08"
        ixy="5.8675E-13"
        ixz="2.4299E-09"
        iyy="9.2485E-08"
        iyz="7.1049E-13"
        izz="8.5586E-08" />
    </inertial>
    <visual>
      <origin
        xyz="0 0 0"
        rpy="0 0 0" />
      <geometry>
        <mesh
          filename="package://ur5_description/meshes/r_thumb_prox.STL" />
      </geometry>
      <material
        name="">
        <color
          rgba="1 1 1 1" />
      </material>
    </visual>
    <collision>
      <origin
        xyz="0 0 0"
        rpy="0 0 0" />
      <geometry>
        <mesh
          filename="package://ur5_description/meshes/r_thumb_prox.STL" />
      </geometry>
    </collision>
  </link>
  <joint
    name="r_thumbCMC"
    type="revolute">
    <origin
      xyz="0.0245 0.0242 0.021628"
      rpy="0 -0.49642 0" />
    <parent
      link="r_palm" />
    <child
      link="r_thumb_prox" />
    <axis
      xyz="0 -1 0" />
    <limit
      lower="0"
      upper="1.5708"
      effort="0"
      velocity="0" />
  </joint>
  <link
    name="r_thumb_dist">
    <inertial>
      <origin
        xyz="0.0083564 0.037204 -3.5884E-07"
        rpy="0 0 0" />
      <mass
        value="0.04" />
      <inertia
        ixx="7.1498E-06"
        ixy="2.0157E-07"
        ixz="-6.0726E-11"
        iyy="9.1501E-07"
        iyz="5.4502E-10"
        izz="6.8747E-06" />
    </inertial>
    <visual>
      <origin
        xyz="0 0 0"
        rpy="0 0 0" />
      <geometry>
        <mesh
          filename="package://ur5_description/meshes/r_thumb_dist.STL" />
      </geometry>
      <material
        name="">
        <color
          rgba="0.75294 0.75294 0.75294 1" />
      </material>
    </visual>
    <collision>
      <origin
        xyz="0 0 0"
        rpy="0 0 0" />
      <geometry>
        <mesh
          filename="package://ur5_description/meshes/r_thumb_dist.STL" />
      </geometry>
    </collision>
  </link>
  <joint
    name="r_thumbMCP"
    type="revolute">
    <origin
      xyz="0.013647 0 0"
      rpy="-0.39332 0.31115 -0.93514" />
    <parent
      link="r_thumb_prox" />
    <child
      link="r_thumb_dist" />
    <axis
      xyz="0 0 1" />
    <limit
      lower="0"
      upper="0.87266"
      effort="0"
      velocity="0" />
  </joint>
  <link
    name="r_index_prox">
    <inertial>
      <origin
        xyz="-5.571E-07 0.016609 0.00045746"
        rpy="0 0 0" />
      <mass
        value="0.008" />
      <inertia
        ixx="3.3526E-07"
        ixy="2.9401E-11"
        ixz="-2.4782E-12"
        iyy="1.0133E-07"
        iyz="2.0576E-08"
        izz="3.7092E-07" />
    </inertial>
    <visual>
      <origin
        xyz="0 0 0"
        rpy="0 0 0" />
      <geometry>
        <mesh
          filename="package://ur5_description/meshes/r_index_prox.STL" />
      </geometry>
      <material
        name="">
        <color
          rgba="0.75294 0.75294 0.75294 1" />
      </material>
    </visual>
    <collision>
      <origin
        xyz="0 0 0"
        rpy="0 0 0" />
      <geometry>
        <mesh
          filename="package://ur5_description/meshes/r_index_prox.STL" />
      </geometry>
    </collision>
  </link>
  <joint
    name="r_indexMCP"
    type="revolute">
    <origin
      xyz="0.029003 0.088231 -0.0039488"
      rpy="-0.09929 -0.054667 -0.031168" />
    <parent
      link="r_palm" />
    <child
      link="r_index_prox" />
    <axis
      xyz="1 0 0" />
    <limit
      lower="0"
      upper="1.309"
      effort="0"
      velocity="0" />
  </joint>
  <link
    name="r_index_dist">
    <inertial>
      <origin
        xyz="5.9401E-06 0.025449 0.003278"
        rpy="0 0 0" />
      <mass
        value="0.011" />
      <inertia
        ixx="8.4801E-07"
        ixy="-1.0878E-09"
        ixz="-1.3683E-10"
        iyy="1.4147E-07"
        iyz="-1.0078E-07"
        izz="8.5502E-07" />
    </inertial>
    <visual>
      <origin
        xyz="0 0 0"
        rpy="0 0 0" />
      <geometry>
        <mesh
          filename="package://ur5_description/meshes/r_index_dist.STL" />
      </geometry>
      <material
        name="">
        <color
          rgba="0.75294 0.75294 0.75294 1" />
      </material>
    </visual>
    <collision>
      <origin
        xyz="0 0 0"
        rpy="0 0 0" />
      <geometry>
        <mesh
          filename="package://ur5_description/meshes/r_index_dist.STL" />
      </geometry>
    </collision>
  </link>
  <joint
    name="r_indexPIP"
    type="revolute">
    <origin
      xyz="0 0.035 0"
      rpy="0.19353 0 0" />
    <parent
      link="r_index_prox" />
    <child
      link="r_index_dist" />
    <axis
      xyz="1 0 0" />
    <limit
      lower="0"
      upper="1.25"
      effort="0"
      velocity="0" />
    <mimic joint="r_indexMCP" multiplier="1.0" offset="0.0"/>
  </joint>
  <link
    name="r_middle_prox">
    <inertial>
      <origin
        xyz="2.3779E-07 0.020205 0.00053993"
        rpy="0 0 0" />
      <mass
        value="0.011" />
      <inertia
        ixx="5.5624E-07"
        ixy="8E-12"
        ixz="-8.5151E-12"
        iyy="1.3298E-07"
        iyz="2.669E-08"
        izz="6.0146E-07" />
    </inertial>
    <visual>
      <origin
        xyz="0 0 0"
        rpy="0 0 0" />
      <geometry>
        <mesh
          filename="package://ur5_description/meshes/r_middle_prox.STL" />
      </geometry>
      <material
        name="">
        <color
          rgba="0.75294 0.75294 0.75294 1" />
      </material>
    </visual>
    <collision>
      <origin
        xyz="0 0 0"
        rpy="0 0 0" />
      <geometry>
        <mesh
          filename="package://ur5_description/meshes/r_middle_prox.STL" />
      </geometry>
    </collision>
  </link>
  <joint
    name="r_middleMCP"
    type="revolute">
    <origin
      xyz="0.008 0.091935 -0.0082038"
      rpy="-0.069813 0 0" />
    <parent
      link="r_palm" />
    <child
      link="r_middle_prox" />
    <axis
      xyz="1 0 0" />
    <limit
      lower="0"
      upper="1.309"
      effort="0"
      velocity="0" />
    <mimic joint="r_indexMCP" multiplier="1.0" offset="0.0"/>
  </joint>
  <link
    name="r_middle_dist">
    <inertial>
      <origin
        xyz="5.9404E-06 0.025449 0.003278"
        rpy="0 0 0" />
      <mass
        value="0.011" />
      <inertia
        ixx="8.4801E-07"
        ixy="-1.0879E-09"
        ixz="-1.3705E-10"
        iyy="1.4147E-07"
        iyz="-1.0078E-07"
        izz="8.5501E-07" />
    </inertial>
    <visual>
      <origin
        xyz="0 0 0"
        rpy="0 0 0" />
      <geometry>
        <mesh
          filename="package://ur5_description/meshes/r_middle_dist.STL" />
      </geometry>
      <material
        name="">
        <color
          rgba="0.75294 0.75294 0.75294 1" />
      </material>
    </visual>
    <collision>
      <origin
        xyz="0 0 0"
        rpy="0 0 0" />
      <geometry>
        <mesh
          filename="package://ur5_description/meshes/r_middle_dist.STL" />
      </geometry>
    </collision>
  </link>
  <joint
    name="r_middlePIP"
    type="revolute">
    <origin
      xyz="0 0.042 0"
      rpy="0.18357 0 0" />
    <parent
      link="r_middle_prox" />
    <child
      link="r_middle_dist" />
    <axis
      xyz="1 0 0" />
    <limit
      lower="0"
      upper="1.25"
      effort="0"
      velocity="0" />
    <mimic joint="r_indexMCP" multiplier="1.0" offset="0.0"/>
  </joint>
  <link
    name="r_ring_prox">
    <inertial>
      <origin
        xyz="2.4507E-07 0.020236 0.00042373"
        rpy="0 0 0" />
      <mass
        value="0.011" />
      <inertia
        ixx="5.5623E-07"
        ixy="7.4604E-12"
        ixz="-8.5876E-12"
        iyy="1.3295E-07"
        iyz="2.7719E-08"
        izz="6.0149E-07" />
    </inertial>
    <visual>
      <origin
        xyz="0 0 0"
        rpy="0 0 0" />
      <geometry>
        <mesh
          filename="package://ur5_description/meshes/r_ring_prox.STL" />
      </geometry>
      <material
        name="">
        <color
          rgba="0.75294 0.75294 0.75294 1" />
      </material>
    </visual>
    <collision>
      <origin
        xyz="0 0 0"
        rpy="0 0 0" />
      <geometry>
        <mesh
          filename="package://ur5_description/meshes/r_ring_prox.STL" />
      </geometry>
    </collision>
  </link>
  <joint
    name="r_ringMCP"
    type="revolute">
    <origin
      xyz="-0.013103 0.089947 -0.0080786"
      rpy="-0.079113 0.054667 0.031168" />
    <parent
      link="r_palm" />
    <child
      link="r_ring_prox" />
    <axis
      xyz="1 0 0" />
    <limit
      lower="0"
      upper="1.309"
      effort="0"
      velocity="0" />
    <mimic joint="r_indexMCP" multiplier="1.0" offset="0.0"/>
  </joint>
  <link
    name="r_ring_dist">
    <inertial>
      <origin
        xyz="5.5799E-07 0.020388 0.0029077"
        rpy="0 0 0" />
      <mass
        value="0.008" />
      <inertia
        ixx="3.6793E-07"
        ixy="-6.504E-13"
        ixz="-1.1541E-11"
        iyy="8.4208E-08"
        iyz="-4.5737E-08"
        izz="3.8369E-07" />
    </inertial>
    <visual>
      <origin
        xyz="0 0 0"
        rpy="0 0 0" />
      <geometry>
        <mesh
          filename="package://ur5_description/meshes/r_ring_dist.STL" />
      </geometry>
      <material
        name="">
        <color
          rgba="0.75294 0.75294 0.75294 1" />
      </material>
    </visual>
    <collision>
      <origin
        xyz="0 0 0"
        rpy="0 0 0" />
      <geometry>
        <mesh
          filename="package://ur5_description/meshes/r_ring_dist.STL" />
      </geometry>
    </collision>
  </link>
  <joint
    name="r_ringPIP"
    type="revolute">
    <origin
      xyz="0 0.042 0"
      rpy="0.16583 0 0" />
    <parent
      link="r_ring_prox" />
    <child
      link="r_ring_dist" />
    <axis
      xyz="1 0 0" />
    <limit
      lower="0"
      upper="1.25"
      effort="0"
      velocity="0" />
    <mimic joint="r_indexMCP" multiplier="1.0" offset="0.0"/>
  </joint>
  <link
    name="r_little_prox">
    <inertial>
      <origin
        xyz="-5.4618E-07 0.016662 0.00040738"
        rpy="0 0 0" />
      <mass
        value="0.008" />
      <inertia
        ixx="3.3526E-07"
        ixy="2.8461E-11"
        ixz="-2.3358E-12"
        iyy="1.0129E-07"
        iyz="2.1346E-08"
        izz="3.7096E-07" />
    </inertial>
    <visual>
      <origin
        xyz="0 0 0"
        rpy="0 0 0" />
      <geometry>
        <mesh
          filename="package://ur5_description/meshes/r_little_prox.STL" />
      </geometry>
      <material
        name="">
        <color
          rgba="0.75294 0.75294 0.75294 1" />
      </material>
    </visual>
    <collision>
      <origin
        xyz="0 0 0"
        rpy="0 0 0" />
      <geometry>
        <mesh
          filename="package://ur5_description/meshes/r_little_prox.STL" />
      </geometry>
    </collision>
  </link>
  <joint
    name="r_littleMCP"
    type="revolute">
    <origin
      xyz="-0.033731 0.083727 -0.0036339"
      rpy="-0.094666 0.057099 0.065996" />
    <parent
      link="r_palm" />
    <child
      link="r_little_prox" />
    <axis
      xyz="1 0 0" />
    <limit
      lower="0"
      upper="1.309"
      effort="0"
      velocity="0" />
    <mimic joint="r_indexMCP" multiplier="1.0" offset="0.0"/>
  </joint>
  <link
    name="r_little_dist">
    <inertial>
      <origin
        xyz="1.062E-05 0.017869 0.0020864"
        rpy="0 0 0" />
      <mass
        value="0.008" />
      <inertia
        ixx="2.3262E-07"
        ixy="-4.9135E-10"
        ixz="-4.9506E-11"
        iyy="6.4304E-08"
        iyz="-2.3564E-08"
        izz="2.4916E-07" />
    </inertial>
    <visual>
      <origin
        xyz="0 0 0"
        rpy="0 0 0" />
      <geometry>
        <mesh
          filename="package://ur5_description/meshes/r_little_dist.STL" />
      </geometry>
      <material
        name="">
        <color
          rgba="0.75294 0.75294 0.75294 1" />
      </material>
    </visual>
    <collision>
      <origin
        xyz="0 0 0"
        rpy="0 0 0" />
      <geometry>
        <mesh
          filename="package://ur5_description/meshes/r_little_dist.STL" />
      </geometry>
    </collision>
  </link>
  <joint
    name="r_littlePIP"
    type="revolute">
    <origin
      xyz="0 0.035 0"
      rpy="0.20294 0 0" />
    <parent
      link="r_little_prox" />
    <child
      link="r_little_dist" />
    <axis
      xyz="1 0 0" />
    <limit
      lower="0"
      upper="1.25"
      effort="0"
      velocity="0" />
    <mimic joint="r_indexMCP" multiplier="1.0" offset="0.0"/>
  </joint>


    <!-- joints main serial chain -->

    <joint name="world2box" type="fixed">
      <parent link="world"/>
      <child link="box"/>
      <origin xyz="0 0 0" rpy="0 0 0"/>
    </joint>

    <joint name="base_fixed_joint" type="fixed">
      <parent link="box"/>
      <child link="base_link"/>
      <origin xyz="0 0 1" rpy="0 0 0"/>
    </joint>

    <joint name="shoulder_pan_joint" type="revolute">
      <parent link="base_link" />
      <child link="shoulder_link" />
      <origin rpy="0 0 0" xyz="0 0 0.1625" />
      <axis xyz="0 0 1" />
      <limit effort="150.0" lower="-6.283185307179586" upper="6.283185307179586"
        velocity="3.141592653589793" />
    </joint>

    <joint name="shoulder_lift_joint" type="revolute">
      <parent link="shoulder_link" />
      <child link="upper_arm_link" />
      <origin rpy="1.5707 1.5707 0" xyz="0 0 0" />
      <axis xyz="0 0 1" />
      <limit effort="150.0" lower="-6.283185307179586" upper="6.283185307179586"
        velocity="3.141592653589793" />
    </joint>

    <joint name="elbow_joint" type="revolute">
      <parent link="upper_arm_link" />
      <child link="forearm_link" />
      <origin rpy="0 0 0" xyz="-0.425 0 0" />
      <axis xyz="0 0 1" />
      <limit effort="150.0" lower="-3.141592653589793" upper="3.141592653589793"
        velocity="3.141592653589793" />
    </joint>

    <joint name="wrist_1_joint" type="revolute">
      <parent link="forearm_link" />
      <child link="wrist_1_link" />
      <origin rpy="0 0 -1.5707" xyz="-0.3922 0 0.1333" />
      <axis xyz="0 0 1" />
      <limit effort="28.0" lower="-6.283185307179586" upper="6.283185307179586"
        velocity="3.141592653589793" />
    </joint>

    <joint name="wrist_2_joint" type="revolute">
      <parent link="wrist_1_link" />
      <child link="wrist_2_link" />
      <origin rpy="1.570796327 0 0" xyz="0 -0.0997 -2.044881182297852e-11" />
      <axis xyz="0 0 1" />
      <limit effort="28.0" lower="-6.283185307179586" upper="6.283185307179586"
        velocity="3.141592653589793" />
    </joint>

    <joint name="wrist_3_joint" type="revolute">
      <parent link="wrist_2_link" />
      <child link="wrist_3_link" />
      <origin rpy="1.570796326589793 3.141592653589793 3.141592653589793"
        xyz="0 0.0996 -2.042830148012698e-11" />
      <axis xyz="0 0 1" />
      <limit effort="28.0" lower="-6.283185307179586" upper="6.283185307179586"
        velocity="3.141592653589793" />
    </joint>

    <link name="ur_arm_flange"/>
    <joint name="ur_arm_wrist_3-flange" type="fixed">
      <parent link="wrist_3_link"/>
      <child link="ur_arm_flange"/>
      <origin rpy="0 -1.5707963267948966 -1.5707963267948966" xyz="0 0 0"/>
    </joint>

    <joint name="base2palm" type="fixed">
      <parent link = "ur_arm_flange"/>
      <child link = "r_palm"/>
      <origin xyz="0 0 0" rpy="1.57 1.57 0"/>
    </joint>

  </xacro:macro>

</robot>
