<?xml version="1.0" ?>
<!-- =================================================================================== -->
<!-- |    This document was autogenerated by xacro from elfin3_joint_link.xacro        | -->
<!-- |    EDITING THIS FILE BY HAND IS NOT RECOMMENDED                                 | -->
<!-- =================================================================================== --> 
<robot name="elfin3">
  <link name="world"/>
  <link name="elfin_base_link"/>
  <joint name="world_base" type="fixed">
    <origin rpy="0 0 0" xyz="0 0 0"/>
    <parent link="world"/>
    <child link="elfin_base_link"/>
  </joint>
  
  <joint name="elfin_base_joint" type="fixed">
    <origin rpy="0 0 1.5707963267948966" xyz="0 0 0"/>
    <parent link="elfin_base_link"/>
    <child link="elfin_base"/>
  </joint>
  <link name="elfin_base">
    <inertial>
      <origin rpy="0 0 0" xyz="0.000476057496448 -0.00609847721085 0.0271227961552"/>
      <mass value="1.3364360054428799"/>
      <inertia ixx="0.0033361494" ixy="1.98687e-05" ixz="6.0873e-06" iyy="0.0027567743999999997" iyz="-3.92121e-05" izz="0.0053986008"/>
    </inertial>
    <visual>
      <origin rpy="0 0 0" xyz="0 0 0"/>
      <geometry>
        <mesh filename="package://elfin_description/meshes/elfin3/elfin_base.STL"/>
      </geometry>
      <material name="metal_white"/>
    </visual>
    <collision>
      <origin rpy="0 0 0" xyz="0 0 0"/>
      <geometry>
        <mesh filename="package://elfin_description/meshes/elfin3/elfin_base.STL"/>
      </geometry>
    </collision>
  </link>
  <link name="elfin_link1">
    <inertial>
      <origin rpy="0 0 0" xyz="-0.0192425632808 0.120157543892 -2.05350524914e-05"/>
      <mass value="4.6968405580113"/>
      <inertia ixx="0.016185883499999998" ixy="0.0037881237000000002" ixz="-4.944e-07" iyy="0.0097480539" iyz="-1.9776e-06" izz="0.0199814541"/>
    </inertial>
    <visual>
      <origin rpy="0 0 0" xyz="0 0 0"/>
      <geometry>
        <mesh filename="package://elfin_description/meshes/elfin3/elfin_link1.STL"/>
      </geometry>
      <material name="metal"/>
    </visual>
    <collision>
      <origin rpy="0 0 0" xyz="0 0 0"/>
      <geometry>
        <mesh filename="package://elfin_description/meshes/elfin3/elfin_link1.STL"/>
      </geometry>
    </collision>
  </link>
  <joint name="elfin_joint1" type="revolute">
    <origin rpy="1.5707963267948966 0 0" xyz="0 0 0.031"/>
    <parent link="elfin_base"/>
    <child link="elfin_link1"/>
    <axis xyz="0 1 0"/>
    <limit effort="104" lower="-3.14" upper="3.14" velocity="1.57"/>
  </joint>
  <link name="elfin_link2">
    <inertial>
      <origin rpy="0 0 0" xyz="-0.0363359816546 0.121774838175 -3.84046105722e-05"/>
      <mass value="1.60578726871323"/>
      <inertia ixx="0.0174527217" ixy="-0.0008180157000000001" ixz="0.0" iyy="0.0016560546" iyz="3.9861e-06" izz="0.016859596199999997"/>
    </inertial>
    <visual>
      <origin rpy="0 0 0" xyz="0 0 0"/>
      <geometry>
        <mesh filename="package://elfin_description/meshes/elfin3/elfin_link2.STL"/>
      </geometry>
      <material name="metal_grey"/>
    </visual>
    <collision>
      <origin rpy="1.57 0 0" xyz="0 0.12 0"/>
      <geometry>
        <cylinder length="0.32" radius="0.05"/>
      </geometry>
    </collision>
  </link>
  <joint name="elfin_joint2" type="revolute">
    <origin rpy="0 0 0" xyz="-0.068808 0.1615 0"/>
    <parent link="elfin_link1"/>
    <child link="elfin_link2"/>
    <axis xyz="-1 0 0"/>
    <limit effort="104" lower="-3.14" upper="3.14" velocity="1.57"/>
  </joint>
  <link name="elfin_link3">
    <inertial>
      <origin rpy="0 0 0" xyz="0.0513625008301 -0.0377418700977 -1.41484011876e-05"/>
      <mass value="3.3222006800226"/>
      <inertia ixx="0.0091655271" ixy="0.0022254489" ixz="2.2557e-06" iyy="0.0056319267" iyz="-1.1433e-06" izz="0.0115212195"/>
    </inertial>
    <visual>
      <origin rpy="0 0 0" xyz="0 0 0"/>
      <geometry>
        <mesh filename="package://elfin_description/meshes/elfin3/elfin_link3.STL"/>
      </geometry>
      <material name="metal"/>
    </visual>
    <collision>
      <origin rpy="0 0 0" xyz="0 0 0"/>
      <geometry>
        <mesh filename="package://elfin_description/meshes/elfin3/elfin_link3.STL"/>
      </geometry>
    </collision>
  </link>
  <joint name="elfin_joint3" type="revolute">
    <origin rpy="-3.141592653589793 0 0" xyz="0 0.266 0"/>
    <parent link="elfin_link2"/>
    <child link="elfin_link3"/>
    <axis xyz="1 0 0"/>
    <limit effort="69" lower="-3.14" upper="3.14" velocity="1.57"/>
  </joint>
  <link name="elfin_link4">
    <inertial>
      <origin rpy="0 0 0" xyz="-0.0580853772834 0.10002233137 -3.45203877103e-06"/>
      <mass value="1.1441233731729"/>
      <inertia ixx="0.0073628211" ixy="0.0025633095" ixz="3.399e-07" iyy="0.0029589221999999997" iyz="-9.888e-07" izz="0.0088114749"/>
    </inertial>
    <visual>
      <origin rpy="0 0 0" xyz="0 0 0"/>
      <geometry>
        <mesh filename="package://elfin_description/meshes/elfin3/elfin_link4.STL"/>
      </geometry>
      <material name="metal_grey"/>
    </visual>
    <collision>
      <origin rpy="1.57 0 0" xyz="0 0 0"/>
      <geometry>
        <cylinder length="0.15" radius="0.05"/>
      </geometry>
    </collision>
  </link>
  <joint name="elfin_joint4" type="revolute">
    <origin rpy="3.141592653589793 0 0" xyz="0.068808 -0.10523 0"/>
    <parent link="elfin_link3"/>
    <child link="elfin_link4"/>
    <axis xyz="0 1 0"/>
    <limit effort="69" lower="-3.14" upper="3.14" velocity="1.57"/>
  </joint>
  <link name="elfin_link5">
    <inertial>
      <origin rpy="0 0 0" xyz="-0.0158710385319 -0.0365214098995 4.94388107361e-07"/>
      <mass value="2.49371418225432"/>
      <inertia ixx="0.0059859171" ixy="0.0014567805" ixz="6.18e-08" iyy="0.0034872812999999997" iyz="-3.399e-07" izz="0.0075907395"/>
    </inertial>
    <visual>
      <origin rpy="0 0 0" xyz="0 0 0"/>
      <geometry>
        <mesh filename="package://elfin_description/meshes/elfin3/elfin_link5.STL"/>
      </geometry>
      <material name="metal"/>
    </visual>
    <collision>
      <origin rpy="0 0 0" xyz="0 0 0"/>
      <geometry>
        <mesh filename="package://elfin_description/meshes/elfin3/elfin_link5.STL"/>
      </geometry>
    </collision>
  </link>
  <joint name="elfin_joint5" type="revolute">
    <origin rpy="-3.141592653589793 0 0" xyz="0 0.21877 0"/>
    <parent link="elfin_link4"/>
    <child link="elfin_link5"/>
    <axis xyz="1 0 0"/>
    <limit effort="34" lower="-3.14" upper="3.14" velocity="1.57"/>
  </joint>
  <link name="elfin_link6">
    <inertial>
      <origin rpy="0 0 0" xyz="-0.0009237 -0.042691 -0.0003367"/>
      <mass value="0.45519408"/>
      <inertia ixx="0.0005996762999999999" ixy="4.326e-06" ixz="-8.9301e-06" iyy="0.0006053928" iyz="1.545e-07" izz="0.0006024263999999999"/>
    </inertial>
    <visual>
      <origin rpy="0 0 0" xyz="0 0 0"/>
      <geometry>
        <mesh filename="package://elfin_description/meshes/elfin3/elfin_link6.STL"/>
      </geometry>
      <material name="metal_white"/>
    </visual>
    <collision>
      <origin rpy="1.57 0 0" xyz="0 0 0"/>
      <geometry>
        <cylinder length="0.2" radius="0.04"/>
      </geometry>
    </collision>
  </link>
  <joint name="elfin_joint6" type="revolute">
    <origin rpy="-3.141592653589793 0 -3.141592653589793" xyz="0 -0.1065 0"/>
    <parent link="elfin_link5"/>
    <child link="elfin_link6"/>
    <axis xyz="0 -1 0"/>
    <limit effort="34" lower="-3.14" upper="3.14" velocity="1.57"/>
  </joint>
  <link name="elfin_end_link"/>
  <joint name="elfin_end_joint" type="fixed">
    <origin rpy="1.5707963267948966 -1.5707963267948966 0" xyz="0 -0.091 0"/>
    <parent link="elfin_link6"/>
    <child link="elfin_end_link"/>
  </joint>
  <link name="elfin_dummy_gripper"/>
  <joint name="elfin_dummy_joint" type="fixed">
    <origin rpy="1.5707963267948966 -1.5707963267948966 0" xyz="0 -0.111 0"/>
    <parent link="elfin_link6"/>
    <child link="elfin_dummy_gripper"/>
  </joint>
</robot>
